Workbook

Sheet Sheet1
B2: Kriteria dan Bobot ROC
B3: Kriteria (Ci​) | C3: Rank (i) | D3: Bobot ROC (Wi​)
B4: Keamanan Transaksi ($C_1$) | C4: 1 | D4: 0.456667
B5: Kelengkapan Produk ($C_2$) | C5: 2 | D5: 0.256667
B6: Kemudahan Penggunaan ($C_3$) | C6: 3 | D6: 0.156667
B7: Biaya Pengiriman & Promo ($C_4$) | C7: 4 | D7: 0.09
B8: Kecepatan Layanan Pelanggan ($C_5$) | C8: 5 | D8: 0.04
F9: Matriks Keputusan Awal
F10: Saya menggunakan skala penilaian 1-5 (1 = Sangat Buruk, 5 = Sangat Baik) dan 4 alternatif e-commerce | Q10: Nilai MIN dan MAX (Per Kriteria)
F11: DM 1 | R11: MIN | Y11: MAX
F12: Alternatif | G12: DM 1 (C1) | H12: DM 1 (C2) | I12: DM 1 (C3) | J12: DM 1 (C4) | K12: DM 1 (C5) | R12: Alternatif | S12: (C1) | T12: (C2) | U12: (C3) | V12: (C4) | W12: (C5) | Y12: Alternatif | Z12: (C1) | AA12: (C2) | AB12: (C3) | AC12: (C4) | AD12: (C5)
F13: Shopee (A1) | G13: 4 | H13: 4 | I13: 5 | J13: 4 | K13: 3 | R13: Shopee (A1) | S13: =MIN(G$13:G$16,G$19:G$22,G$25:G$28) -> 3 | T13: =MIN(H$13:H$16,H$19:H$22,H$25:H$28) -> 2 | U13: =MIN(I$13:I$16,I$19:I$22,I$25:I$28) -> 3 | V13: =MIN(J$13:J$16,J$19:J$22,J$25:J$28) -> 3 | W13: =MIN(K$13:K$16,K$19:K$22,K$25:K$28) -> 2 | Y13: Shopee (A1) | Z13: =MAX(G$13:G$16,G$19:G$22,G$25:G$28) -> 5 | AA13: =MAX(H$13:H$16,H$19:H$22,H$25:H$28) -> 13 | AB13: =MAX(I$13:I$16,I$19:I$22,I$25:I$28) -> 5 | AC13: =MAX(J$13:J$16,J$19:J$22,J$25:J$28) -> 5 | AD13: =MAX(K$13:K$16,K$19:K$22,K$25:K$28) -> 5
F14: Tokopedia (A2) | G14: 5 | H14: 2 | I14: 4 | J14: 3 | K14: 4 | R14: Tokopedia (A2) | S14: =MIN(G$13:G$16,G$19:G$22,G$25:G$28) -> 3 | T14: =MIN(H$13:H$16,H$19:H$22,H$25:H$28) -> 2 | U14: =MIN(I$13:I$16,I$19:I$22,I$25:I$28) -> 3 | V14: =MIN(J$13:J$16,J$19:J$22,J$25:J$28) -> 3 | W14: =MIN(K$13:K$16,K$19:K$22,K$25:K$28) -> 2 | Y14: Tokopedia (A2) | Z14: =MAX(G$13:G$16,G$19:G$22,G$25:G$28) -> 5 | AA14: =MAX(H$13:H$16,H$19:H$22,H$25:H$28) -> 13 | AB14: =MAX(I$13:I$16,I$19:I$22,I$25:I$28) -> 5 | AC14: =MAX(J$13:J$16,J$19:J$22,J$25:J$28) -> 5 | AD14: =MAX(K$13:K$16,K$19:K$22,K$25:K$28) -> 5
F15: Lazada (A3) | G15: 5 | H15: 5 | I15: 4 | J15: 5 | K15: 3 | R15: Lazada (A3) | S15: =MIN(G$13:G$16,G$19:G$22,G$25:G$28) -> 3 | T15: =MIN(H$13:H$16,H$19:H$22,H$25:H$28) -> 2 | U15: =MIN(I$13:I$16,I$19:I$22,I$25:I$28) -> 3 | V15: =MIN(J$13:J$16,J$19:J$22,J$25:J$28) -> 3 | W15: =MIN(K$13:K$16,K$19:K$22,K$25:K$28) -> 2 | Y15: Lazada (A3) | Z15: =MAX(G$13:G$16,G$19:G$22,G$25:G$28) -> 5 | AA15: =MAX(H$13:H$16,H$19:H$22,H$25:H$28) -> 13 | AB15: =MAX(I$13:I$16,I$19:I$22,I$25:I$28) -> 5 | AC15: =MAX(J$13:J$16,J$19:J$22,J$25:J$28) -> 5 | AD15: =MAX(K$13:K$16,K$19:K$22,K$25:K$28) -> 5
F16: Blibli (A4) | G16: 3 | H16: 3 | I16: 4 | J16: 4 | K16: 5 | R16: Blibli (A4) | S16: =MIN(G$13:G$16,G$19:G$22,G$25:G$28) -> 3 | T16: =MIN(H$13:H$16,H$19:H$22,H$25:H$28) -> 2 | U16: =MIN(I$13:I$16,I$19:I$22,I$25:I$28) -> 3 | V16: =MIN(J$13:J$16,J$19:J$22,J$25:J$28) -> 3 | W16: =MIN(K$13:K$16,K$19:K$22,K$25:K$28) -> 2 | Y16: Blibli (A4) | Z16: =MAX(G$13:G$16,G$19:G$22,G$25:G$28) -> 5 | AA16: =MAX(H$13:H$16,H$19:H$22,H$25:H$28) -> 13 | AB16: =MAX(I$13:I$16,I$19:I$22,I$25:I$28) -> 5 | AC16: =MAX(J$13:J$16,J$19:J$22,J$25:J$28) -> 5 | AD16: =MAX(K$13:K$16,K$19:K$22,K$25:K$28) -> 5
F17: DM 2
F18: Alternatif | G18: DM 2 (C1) | H18: DM 2 (C2) | I18: DM 2 (C3) | J18: DM 2 (C4) | K18: DM 2 (C5)
F19: Shopee (A1) | G19: 5 | H19: 13 | I19: 4 | J19: 3 | K19: 4
F20: Tokopedia (A2) | G20: 4 | H20: 5 | I20: 3 | J20: 4 | K20: 5
F21: Lazada (A3) | G21: 3 | H21: 3 | I21: 4 | J21: 5 | K21: 4
F22: Blibli (A4) | G22: 4 | H22: 4 | I22: 5 | J22: 4 | K22: 3
F23: DM 3
F24: Alternatif | G24: DM 3 (C1) | H24: DM 3 (C2) | I24: DM 3 (C3) | J24: DM 3 (C4) | K24: DM 3 (C5)
F25: Shopee (A1) | G25: 3 | H25: 5 | I25: 3 | J25: 4 | K25: 2
F26: Tokopedia (A2) | G26: 5 | H26: 4 | I26: 5 | J26: 3 | K26: 4
F27: Lazada (A3) | G27: 4 | H27: 4 | I27: 3 | J27: 4 | K27: 5
F28: Blibli (A4) | G28: 3 | H28: 3 | I28: 4 | J28: 3 | K28: 4
F31: Normalisasi | R31: Nilai Akhir Terbobot
F32: DM 1 | R32: DM 1
F33: Alternatif | G33: DM 1 (C1) | H33: DM 1 (C2) | I33: DM 1 (C3) | J33: DM 1 (C4) | K33: DM 1 (C5) | R33: Alternatif | U33: RANK
F34: Shopee (A1) | G34: =(G13 - S$13) / (Z$13 - S$13) -> 0.5 | H34: =(H13 - T$13) / (AA$13 - T$13) -> 0.18181818 | I34: =(I13 - U$13) / (AB$13 - U$13) -> 1 | J34: =(J13 - V$13) / (AC$13 - V$13) -> 0.5 | K34: =(K13 - W$13) / (AD$13 - W$13) -> 0.33333333 | R34: Shopee (A1) | S34: =SUMPRODUCT(G34:K34, Sheet2!$C$2:$G$2) -> 0.49000056 | U34: =RANK(S34,S$34:S$37,0) -> 3
F35: Tokopedia (A2) | G35: =(G14 - S$13) / (Z$13 - S$13) -> 1 | H35: =(H14 - T$13) / (AA$13 - T$13) -> 0 | I35: =(I14 - U$13) / (AB$13 - U$13) -> 0.5 | J35: =(J14 - V$13) / (AC$13 - V$13) -> 0 | K35: =(K14 - W$13) / (AD$13 - W$13) -> 0.66666667 | R35: Tokopedia (A2) | S35: =SUMPRODUCT(G35:K35, Sheet2!$C$2:$G$2) -> 0.56166717 | U35: =RANK(S35,S$34:S$37,0) -> 2
F36: Lazada (A3) | G36: =(G15 - S$13) / (Z$13 - S$13) -> 1 | H36: =(H15 - T$13) / (AA$13 - T$13) -> 0.27272727 | I36: =(I15 - U$13) / (AB$13 - U$13) -> 0.5 | J36: =(J15 - V$13) / (AC$13 - V$13) -> 1 | K36: =(K15 - W$13) / (AD$13 - W$13) -> 0.33333333 | R36: Lazada (A3) | S36: =SUMPRODUCT(G36:K36, Sheet2!$C$2:$G$2) -> 0.70833392 | U36: =RANK(S36,S$34:S$37,0) -> 1
F37: Blibli (A4) | G37: =(G16 - S$13) / (Z$13 - S$13) -> 0 | H37: =(H16 - T$13) / (AA$13 - T$13) -> 0.090909091 | I37: =(I16 - U$13) / (AB$13 - U$13) -> 0.5 | J37: =(J16 - V$13) / (AC$13 - V$13) -> 0.5 | K37: =(K16 - W$13) / (AD$13 - W$13) -> 1 | R37: Blibli (A4) | S37: =SUMPRODUCT(G37:K37, Sheet2!$C$2:$G$2) -> 0.18666686 | U37: =RANK(S37,S$34:S$37,0) -> 4
F38: DM 2 | R38: DM 2
F39: Alternatif | G39: DM 1 (C1) | H39: DM 1 (C2) | I39: DM 1 (C3) | J39: DM 1 (C4) | K39: DM 1 (C5) | R39: Alternatif | U39: RANK
F40: Shopee (A1) | G40: =(G19 - S$13) / (Z$13 - S$13) -> 1 | H40: =(H19 - T$13) / (AA$13 - T$13) -> 1 | I40: =(I19 - U$13) / (AB$13 - U$13) -> 0.5 | J40: =(J19 - V$13) / (AC$13 - V$13) -> 0 | K40: =(K19 - W$13) / (AD$13 - W$13) -> 0.66666667 | R40: Shopee (A1) | S40: =SUMPRODUCT(G40:K40, Sheet2!$C$2:$G$2) -> 0.81833417 | U40: =RANK(S40,S$40:S$43,0) -> 1
F41: Tokopedia (A2) | G41: =(G20 - S$13) / (Z$13 - S$13) -> 0.5 | H41: =(H20 - T$13) / (AA$13 - T$13) -> 0.27272727 | I41: =(I20 - U$13) / (AB$13 - U$13) -> 0 | J41: =(J20 - V$13) / (AC$13 - V$13) -> 0.5 | K41: =(K20 - W$13) / (AD$13 - W$13) -> 1 | R41: Tokopedia (A2) | S41: =SUMPRODUCT(G41:K41, Sheet2!$C$2:$G$2) -> 0.38333359 | U41: =RANK(S41,S$40:S$43,0) -> 3 | Y41: DM 1, Lazada (A3)
F42: Lazada (A3) | G42: =(G21 - S$13) / (Z$13 - S$13) -> 0 | H42: =(H21 - T$13) / (AA$13 - T$13) -> 0.090909091 | I42: =(I21 - U$13) / (AB$13 - U$13) -> 0.5 | J42: =(J21 - V$13) / (AC$13 - V$13) -> 1 | K42: =(K21 - W$13) / (AD$13 - W$13) -> 0.66666667 | R42: Lazada (A3) | S42: =SUMPRODUCT(G42:K42, Sheet2!$C$2:$G$2) -> 0.21833353 | U42: =RANK(S42,S$40:S$43,0) -> 4 | Y42: DM 2, Shopee (A1)
F43: Blibli (A4) | G43: =(G22 - S$13) / (Z$13 - S$13) -> 0.5 | H43: =(H22 - T$13) / (AA$13 - T$13) -> 0.18181818 | I43: =(I22 - U$13) / (AB$13 - U$13) -> 1 | J43: =(J22 - V$13) / (AC$13 - V$13) -> 0.5 | K43: =(K22 - W$13) / (AD$13 - W$13) -> 0.33333333 | R43: Blibli (A4) | S43: =SUMPRODUCT(G43:K43, Sheet2!$C$2:$G$2) -> 0.49000056 | U43: =RANK(S43,S$40:S$43,0) -> 2 | Y43: DM 3, Tokopedia (A2)
...

Sheet Sheet2
C2: 0.456667 | D2: 0.256667 | E2: 0.156667 | F2: 0.09 | G2: 0.04 | H2: 0.456667 | I2: 0.256667 | J2: 0.156667 | K2: 0.09 | L2: 0.04 | M2: 0.456667 | N2: 0.256667 | O2: 0.156667 | P2: 0.09 | Q2: 0.04 | AA2: Normalisasi
B3: Alternatif | C3: DM 1 (C1) | D3: DM 1 (C2) | E3: DM 1 (C3) | F3: DM 1 (C4) | G3: DM 1 (C5) | H3: DM 2 (C1) | I3: DM 2 (C2) | J3: DM 2 (C3) | K3: DM 2 (C4) | L3: DM 2 (C5) | M3: DM 3 (C1) | N3: DM 3 (C2) | O3: DM 3 (C3) | P3: DM 3 (C4) | Q3: DM 3 (C5) | T3: C1 | U3: C2 | V3: C3 | W3: C4 | X3: C5 | Y3: C1 | Z3: C2 | AA3: C3 | AB3: C4 | AC3: C5 | AD3: C1 | AE3: C2 | AF3: C3 | AG3: C4 | AH3: C5 | AL3: Rank (i) | AM3: Bobot ROC (Wi​)
B4: Shopee (A1) | C4: 4 | D4: 5 | E4: 5 | F4: 4 | G4: 3 | H4: 5 | I4: 4 | J4: 4 | K4: 3 | L4: 4 | M4: 4 | N4: 5 | O4: 4 | P4: 5 | Q4: 3 | S4: MIN | T4: =MIN(C$4:C$7, H$4:H$7, M$4:M$7) -> 3 | U4: =MIN(D$4:D$7, I$4:I$7, N$4:N$7) -> 3 | V4: =MIN(E$4:E$7, J$4:J$7, O$4:O$7) -> 3 | W4: =MIN(F$4:F$7, K$4:K$7, P$4:P$7) -> 3 | X4: =MIN(G$4:G$7, L$4:L$7, Q$4:Q$7) -> 3 | Y4: =MIN(H$4:H$7, M$4:M$7, R$4:R$7) -> 3 | Z4: =MIN(I$4:I$7, N$4:N$7, S$4:S$7) -> 3 | AA4: =MIN(J$4:J$7, O$4:O$7, T$4:T$7) -> 3 | ... AH4: =MIN(Q$4:Q$7, V$4:V$7, AA$4:AA$7) -> 3 | AK4: Keamanan Transaksi ($C_1$) | AL4: 1 | AM4: 0.456667
B5: Tokopedia (A2) | C5: 5 | D5: 4 | E5: 4 | F5: 3 | G5: 4 | H5: 4 | I5: 5 | J5: 3 | K5: 4 | L5: 5 | M5: 5 | N5: 4 | O5: 5 | P5: 3 | Q5: 4 | S5: MAX | T5: =MAX(C$4:C$7, H$4:H$7, M$4:M$7) -> 5 | U5: =MAX(D$4:D$7, I$4:I$7, N$4:N$7) -> 5 | V5: =MAX(E$4:E$7, J$4:J$7, O$4:O$7) -> 5 | W5: =MAX(F$4:F$7, K$4:K$7, P$4:P$7) -> 5 | X5: =MAX(G$4:G$7, L$4:L$7, Q$4:Q$7) -> 5 | Y5: =MAX(H$4:H$7, M$4:M$7, R$4:R$7) -> 5 | Z5: =MAX(I$4:I$7, N$4:N$7, S$4:S$7) -> 5 | AA5: =MAX(J$4:J$7, O$4:O$7, T$4:T$7) -> 5 | ... AH5: =MAX(Q$4:Q$7, V$4:V$7, AA$4:AA$7) -> 5 | AK5: Kelengkapan Produk ($C_2$) | AL5: 2 | AM5: 0.256667
B6: Lazada (A3) | C6: 4 | D6: 4 | E6: 3 | F6: 5 | G6: 3 | H6: 3 | I6: 3 | J6: 4 | K6: 5 | L6: 4 | M6: 4 | N6: 4 | O6: 3 | P6: 4 | Q6: 5 | AK6: Kemudahan Penggunaan ($C_3$) | AL6: 3 | AM6: 0.156667
B7: Blibli (A4) | C7: 3 | D7: 3 | E7: 4 | F7: 4 | G7: 5 | H7: 4 | I7: 4 | J7: 5 | K7: 4 | L7: 3 | M7: 3 | N7: 3 | O7: 4 | P7: 3 | Q7: 4 | AK7: Biaya Pengiriman & Promo ($C_4$) | AL7: 4 | AM7: 0.09
AK8: Kecepatan Layanan Pelanggan ($C_5$) | AL8: 5 | AM8: 0.04
B10: Shopee (A1) | C10: =(C4 - T$4) / (T$5 - T$4) -> 0.5 | D10: =(D4 - U$4) / (U$5 - U$4) -> 1 | E10: =(E4 - V$4) / (V$5 - V$4) -> 1 | F10: =(F4 - W$4) / (W$5 - W$4) -> 0.5 | G10: =(G4 - X$4) / (X$5 - X$4) -> 0 | H10: =(H4 - Y$4) / (Y$5 - Y$4) -> 1 | I10: =(I4 - Z$4) / (Z$5 - Z$4) -> 0.5 | J10: =(J4 - AA$4) / (AA$5 - AA$4) -> 0.5 | ... Q10: =(Q4 - AH$4) / (AH$5 - AH$4) -> 0
B11: Tokopedia (A2) | C11: =(C5 - T$4) / (T$5 - T$4) -> 1 | D11: =(D5 - U$4) / (U$5 - U$4) -> 0.5 | E11: =(E5 - V$4) / (V$5 - V$4) -> 0.5 | F11: =(F5 - W$4) / (W$5 - W$4) -> 0 | G11: =(G5 - X$4) / (X$5 - X$4) -> 0.5 | H11: =(H5 - Y$4) / (Y$5 - Y$4) -> 0.5 | I11: =(I5 - Z$4) / (Z$5 - Z$4) -> 1 | J11: =(J5 - AA$4) / (AA$5 - AA$4) -> 0 | ... Q11: =(Q5 - AH$4) / (AH$5 - AH$4) -> 0.5
B12: Lazada (A3) | C12: =(C6 - T$4) / (T$5 - T$4) -> 0.5 | D12: =(D6 - U$4) / (U$5 - U$4) -> 0.5 | E12: =(E6 - V$4) / (V$5 - V$4) -> 0 | F12: =(F6 - W$4) / (W$5 - W$4) -> 1 | G12: =(G6 - X$4) / (X$5 - X$4) -> 0 | H12: =(H6 - Y$4) / (Y$5 - Y$4) -> 0 | I12: =(I6 - Z$4) / (Z$5 - Z$4) -> 0 | J12: =(J6 - AA$4) / (AA$5 - AA$4) -> 0.5 | ... Q12: =(Q6 - AH$4) / (AH$5 - AH$4) -> 1
B13: Blibli (A4) | C13: =(C7 - T$4) / (T$5 - T$4) -> 0 | D13: =(D7 - U$4) / (U$5 - U$4) -> 0 | E13: =(E7 - V$4) / (V$5 - V$4) -> 0.5 | F13: =(F7 - W$4) / (W$5 - W$4) -> 0.5 | G13: =(G7 - X$4) / (X$5 - X$4) -> 1 | H13: =(H7 - Y$4) / (Y$5 - Y$4) -> 0.5 | I13: =(I7 - Z$4) / (Z$5 - Z$4) -> 0.5 | J13: =(J7 - AA$4) / (AA$5 - AA$4) -> 1 | ... Q13: =(Q7 - AH$4) / (AH$5 - AH$4) -> 0.5
C15: NILAI AKHIR
C16: DM 1
B17: Shopee (A1) | C17: =SUMPRODUCT(C10:G10, $C$2:$G$2) -> 0.6866675 | E17: =RANK(C17, $C$17:$C$20, 0) -> 1
B18: Tokopedia (A2) | C18: =SUMPRODUCT(C11:G11, $C$2:$G$2) -> 0.683334 | E18: =RANK(C18, $C$17:$C$20, 0) -> 2
B19: Lazada (A3) | C19: =SUMPRODUCT(C12:G12, $C$2:$G$2) -> 0.446667 | E19: =RANK(C19, $C$17:$C$20, 0) -> 3
B20: Blibli (A4) | C20: =SUMPRODUCT(C13:G13, $C$2:$G$2) -> 0.1633335 | E20: =RANK(C20, $C$17:$C$20, 0) -> 4
C22: DM 2
B23: Shopee (A1) | C23: =SUMPRODUCT(H10:L10, $C$2:$G$2) -> 0.683334
B24: Tokopedia (A2) | C24: =SUMPRODUCT(H11:L11, $C$2:$G$2) -> 0.5700005
B25: Lazada (A3) | C25: =SUMPRODUCT(H12:L12, $C$2:$G$2) -> 0.1883335
B26: Blibli (A4) | C26: =SUMPRODUCT(H13:L13, $C$2:$G$2) -> 0.558334
C28: DM 3
B29: Shopee (A1) | C29: =SUMPRODUCT(M10:Q10, $C$2:$G$2) -> 0.653334
B30: Tokopedia (A2) | C30: =SUMPRODUCT(M11:Q11, $C$2:$G$2) -> 0.7616675
B31: Lazada (A3) | C31: =SUMPRODUCT(M12:Q12, $C$2:$G$2) -> 0.441667
B32: Blibli (A4) | C32: =SUMPRODUCT(M13:Q13, $C$2:$G$2) -> 0.0983335
